Workbook

Sheet Cover
B1: MULTIFAMILY UNDERWRITING MODEL
B2: Rescia Properties · Multifamily Mastery · Institutional Template v1.1
B5: Deal Name | C5: [Enter Deal Name]
B6: Location (City, State) | C6: [City, ST]
B7: Analyst | C7: [Analyst Name]
B8: Date | C8: [YYYY-MM-DD]
B10: MODEL CONVENTIONS
B11: Blue text | C11: Hardcoded inputs — edit on Assumptions sheet
B12: Black text | C12: Formulas — do not overwrite
B13: Green text | C13: Cross-sheet links
B14: Yellow background | C14: Key assumptions requiring attention
B15: Currency | C15: USD; negatives in parentheses
B16: Units | C16: Per-unit figures labeled '/unit'; annual unless noted
B18: SHEETS IN THIS WORKBOOK
B19: 1. Cover | C19: This page
B20: 2. Assumptions | C20: All hardcoded inputs
B21: 3. Rent Roll | C21: Unit mix
B22: 4. Proforma | C22: 5-year NOI
B23: 5. Debt & Equity | C23: Capital stack & DSCR
B24: 6. Returns | C24: IRR, multiple, CoC
B25: 7. Sensitivity | C25: Exit cap × rent growth
B26: 8. Sources & Uses | C26: Closing capitalization
B29: Private & Confidential · Rescia Properties, LLC · © 2026

Sheet Assumptions
B1: Assumptions & Inputs
B2: All hardcoded inputs live on this sheet
B4: ACQUISITION
B5: Purchase Price | C5: 30000000 | D5: Gross purchase price
B6: Unit Count | C6: 200 | D6: Total residential units
B7: Price Per Unit | C7: =Assumptions!$C$5/Assumptions!$C$6 -> 150000 | D7: Calc
B8: Going-in Cap Rate | C8: 0.055 | D8: Trailing or Year 1
B9: Year Built | C9: 1998 | D9: Original construction
B10: Square Footage (total) | C10: 175000 | D10: Net rentable
B11: Closing Costs (%) | C11: 0.015 | D11: Legal, title, lender
B12: Acquisition Fee (%) | C12: 0.015 | D12: GP fee
B14: OPERATING — YEAR 1 INPUTS
B15: Average Market Rent (in-place) | C15: 1450 | D15: $/unit/month
B16: Loss to Lease | C16: 0.03 | D16: Market − in-place gap
B17: Physical Vacancy | C17: 0.05 | D17: Year 1
B18: Concessions | C18: 0.01 | D18: % of GPR
B19: Bad Debt | C19: 0.01 | D19: % of GPR
B20: Other Income ($/unit/mo) | C20: 85 | D20: Laundry, RUBS, pet
B21: Payroll ($/unit/yr) | C21: 1400 | D21: Bench $1.2-1.8k
B22: R&M ($/unit/yr) | C22: 550 | D22: Bench $400-700
B23: Marketing ($/unit/yr) | C23: 120 | D23: Bench $100-175
B24: Admin ($/unit/yr) | C24: 200 | D24: Office, legal
B25: Utilities ($/unit/yr) | C25: 350 | D25: Common area
B26: Insurance ($/unit/yr) | C26: 325 | D26: Get a broker quote
... B30: Replacement Reserves ($/unit/yr) | C30: 300 | D30: Lender $250-300
B32: GROWTH & EXIT
B33: Rent Growth (Yrs 2-5) | C33: 0.03 | D33: Compounded annual
B34: Expense Growth (Yrs 2-5) | C34: 0.025 | D34: Excludes taxes
B35: Property Tax Growth | C35: 0.04 | D35: Reassessed base
B36: Other Income Growth | C36: 0.025 | D36: Annual
B37: Exit Cap Rate | C37: 0.0575 | D37: Entry +25-75 bps
B38: Cost of Sale | C38: 0.02 | D38: Broker + closing
B39: Hold Period (years) | C39: 5 | D39: Base case
B41: DEBT & EQUITY
B42: Loan-to-Cost (LTC) | C42: 0.65 | D42: Target 65%
B43: Interest Rate | C43: 0.06 | D43: Agency coupon
B44: Amortization (years) | C44: 30 | D44: Standard agency
B45: Interest-Only Period (years) | C45: 2 | D45: 2 yrs typical
B46: Loan Term (years) | C46: 5 | D46: Match hold
B47: Loan Origination (%) | C47: 0.01 | D47: 1% typical
...

Sheet Rent Roll
B1: Unit Mix & Rent Roll
B2: In-place composition
B4: Unit Type | C4: Bed/Bath | D4: Units | E4: SF/Unit | F4: Total SF | G4: In-Place Rent | H4: Market Rent | I4: Monthly Total
B5: A1 - Studio | C5: 0/1 | D5: 30 | E5: 525 | F5: =D5*E5 -> 15750 | G5: 1050 | H5: 1200 | I5: =D5*G5 -> 31500
B6: B1 - 1BR | C6: 1/1 | D6: 80 | E6: 750 | F6: =D6*E6 -> 60000 | G6: 1350 | H6: 1450 | I6: =D6*G6 -> 108000
B7: B2 - 1BR Premium | C7: 1/1 | D7: 40 | E7: 825 | F7: =D7*E7 -> 33000 | G7: 1450 | H7: 1550 | I7: =D7*G7 -> 58000
B8: C1 - 2BR | C8: 2/2 | D8: 50 | E8: 1050 | F8: =D8*E8 -> 52500 | G8: 1750 | H8: 1900 | I8: =D8*G8 -> 87500
B9: TOTAL / WEIGHTED AVG | D9: =SUM(D5:D8) -> 200 | F9: =SUM(F5:F8) -> 161250 | G9: =SUMPRODUCT(D5:D8,G5:G8)/D9 -> 1425 | H9: =SUMPRODUCT(D5:D8,H5:H8)/D9 -> 1545 | I9: =SUM(I5:I8) -> 285000
B11: Annual Gross Potential (in-place) | C11: =I9*12 -> 3420000
B12: Annual Gross Potential (market) | C12: =SUMPRODUCT(D5:D8,H5:H8)*12 -> 3708000
B13: Implied Loss to Lease | C13: =1-C11/C12 -> 0.077669903
B16: Private & Confidential · Rescia Properties, LLC · © 2026

Sheet Proforma
B1: 5-Year Operating Proforma
B2: Revenue, expenses, NOI
B4: Line Item | C4: Year 1 | D4: Year 2 | E4: Year 3 | F4: Year 4 | G4: Year 5 | H4: 5-Yr Total | I4: CAGR
B5: REVENUE
B6: Gross Potential Rent | C6: =Assumptions!$C$15*Assumptions!$C$6*12 -> 3480000 | D6: =C6*(1+Assumptions!$C$33) -> 3584400 | E6: =D6*(1+Assumptions!$C$33) -> 3691932 | F6: =E6*(1+Assumptions!$C$33) -> 3802690 | G6: =F6*(1+Assumptions!$C$33) -> 3916770.7 | H6: =SUM(C6:G6) -> 18475793 | I6: =IFERROR((G6/C6)^(1/4)-1,0) -> 0.03
B7: (Less) Loss to Lease | C7: =-C6*Assumptions!$C$16 -> -104400 | D7: =-D6*Assumptions!$C$16 -> -107532 | E7: =-E6*Assumptions!$C$16 -> -110757.96 | F7: =-F6*Assumptions!$C$16 -> -114080.7 | G7: =-G6*Assumptions!$C$16 -> -117503.12 | H7: =SUM(C7:G7) -> -554273.78
B8: (Less) Vacancy | C8: =-C6*Assumptions!$C$17 -> -174000 | D8: =-D6*Assumptions!$C$17 -> -179220 | E8: =-E6*Assumptions!$C$17 -> -184596.6 | F8: =-F6*Assumptions!$C$17 -> -190134.5 | G8: =-G6*Assumptions!$C$17 -> -195838.53 | H8: =SUM(C8:G8) -> -923789.63
B9: (Less) Concessions | C9: =-C6*Assumptions!$C$18 -> -34800 | D9: =-D6*Assumptions!$C$18 -> -35844 | E9: =-E6*Assumptions!$C$18 -> -36919.32 | F9: =-F6*Assumptions!$C$18 -> -38026.9 | G9: =-G6*Assumptions!$C$18 -> -39167.707 | H9: =SUM(C9:G9) -> -184757.93
B10: (Less) Bad Debt | C10: =-C6*Assumptions!$C$19 -> -34800 | D10: =-D6*Assumptions!$C$19 -> -35844 | E10: =-E6*Assumptions!$C$19 -> -36919.32 | F10: =-F6*Assumptions!$C$19 -> -38026.9 | G10: =-G6*Assumptions!$C$19 -> -39167.707 | H10: =SUM(C10:G10) -> -184757.93
B11: Net Rental Income | C11: =SUM(C6:C10) -> 3132000 | D11: =SUM(D6:D10) -> 3225960 | E11: =SUM(E6:E10) -> 3322738.8 | F11: =SUM(F6:F10) -> 3422421 | G11: =SUM(G6:G10) -> 3525093.6 | H11: =SUM(C11:G11) -> 16628213
B12: Other Income | C12: =Assumptions!$C$20*Assumptions!$C$6*12 -> 204000 | D12: =C12*(1+Assumptions!$C$36) -> 209100 | E12: =D12*(1+Assumptions!$C$36) -> 214327.5 | F12: =E12*(1+Assumptions!$C$36) -> 219685.69 | G12: =F12*(1+Assumptions!$C$36) -> 225177.83 | H12: =SUM(C12:G12) -> 1072291
B13: EFFECTIVE GROSS INCOME | C13: =C11+C12 -> 3336000 | D13: =D11+D12 -> 3435060 | E13: =E11+E12 -> 3537066.3 | F13: =F11+F12 -> 3642106.7 | G13: =G11+G12 -> 3750271.4 | H13: =SUM(C13:G13) -> 17700504 | I13: =IFERROR((G13/C13)^(1/4)-1,0) -> 0.02969633
B15: OPERATING EXPENSES
B16: Payroll | C16: =Assumptions!$C$21*Assumptions!$C$6 -> 280000 | D16: =C16*(1+Assumptions!$C$34) -> 287000 | E16: =D16*(1+Assumptions!$C$34) -> 294175 | F16: =E16*(1+Assumptions!$C$34) -> 301529.38 | G16: =F16*(1+Assumptions!$C$34) -> 309067.61 | H16: =SUM(C16:G16) -> 1471772
B17: Repairs & Maintenance | C17: =Assumptions!$C$22*Assumptions!$C$6 -> 110000 | D17: =C17*(1+Assumptions!$C$34) -> 112750 | E17: =D17*(1+Assumptions!$C$34) -> 115568.75 | F17: =E17*(1+Assumptions!$C$34) -> 118457.97 | G17: =F17*(1+Assumptions!$C$34) -> 121419.42 | H17: =SUM(C17:G17) -> 578196.14
B18: Marketing | C18: =Assumptions!$C$23*Assumptions!$C$6 -> 24000 | D18: =C18*(1+Assumptions!$C$34) -> 24600 | E18: =D18*(1+Assumptions!$C$34) -> 25215 | F18: =E18*(1+Assumptions!$C$34) -> 25845.375 | G18: =F18*(1+Assumptions!$C$34) -> 26491.509 | H18: =SUM(C18:G18) -> 126151.88
B19: Administrative | C19: =Assumptions!$C$24*Assumptions!$C$6 -> 40000 | D19: =C19*(1+Assumptions!$C$34) -> 41000 | E19: =D19*(1+Assumptions!$C$34) -> 42025 | F19: =E19*(1+Assumptions!$C$34) -> 43075.625 | G19: =F19*(1+Assumptions!$C$34) -> 44152.516 | H19: =SUM(C19:G19) -> 210253.14
B20: Utilities | C20: =Assumptions!$C$25*Assumptions!$C$6 -> 70000 | D20: =C20*(1+Assumptions!$C$34) -> 71750 | E20: =D20*(1+Assumptions!$C$34) -> 73543.75 | F20: =E20*(1+Assumptions!$C$34) -> 75382.344 | G20: =F20*(1+Assumptions!$C$34) -> 77266.902 | H20: =SUM(C20:G20) -> 367943
B21: Insurance | C21: =Assumptions!$C$26*Assumptions!$C$6 -> 65000 | D21: =C21*(1+Assumptions!$C$34) -> 66625 | E21: =D21*(1+Assumptions!$C$34) -> 68290.625 | F21: =E21*(1+Assumptions!$C$34) -> 69997.891 | G21: =F21*(1+Assumptions!$C$34) -> 71747.838 | H21: =SUM(C21:G21) -> 341661.35
B22: Property Taxes | C22: =Assumptions!$C$27*Assumptions!$C$6 -> 440000 | D22: =C22*(1+Assumptions!$C$35) -> 457600 | E22: =D22*(1+Assumptions!$C$35) -> 475904 | F22: =E22*(1+Assumptions!$C$35) -> 494940.16 | G22: =F22*(1+Assumptions!$C$35) -> 514737.77 | H22: =SUM(C22:G22) -> 2383181.9
B23: Contract Services | C23: =Assumptions!$C$28*Assumptions!$C$6 -> 90000 | D23: =C23*(1+Assumptions!$C$34) -> 92250 | E23: =D23*(1+Assumptions!$C$34) -> 94556.25 | F23: =E23*(1+Assumptions!$C$34) -> 96920.156 | G23: =F23*(1+Assumptions!$C$34) -> 99343.16 | H23: =SUM(C23:G23) -> 473069.57
B24: Management Fee | C24: =C13*Assumptions!$C$29 -> 116760 | D24: =D13*Assumptions!$C$29 -> 120227.1 | E24: =E13*Assumptions!$C$29 -> 123797.32 | F24: =F13*Assumptions!$C$29 -> 127473.73 | G24: =G13*Assumptions!$C$29 -> 131259.5 | H24: =SUM(C24:G24) -> 619517.65
B25: TOTAL OPERATING EXPENSES | C25: =SUM(C16:C24) -> 1235760 | D25: =SUM(D16:D24) -> 1273802.1 | E25: =SUM(E16:E24) -> 1313075.7 | F25: =SUM(F16:F24) -> 1353622.6 | G25: =SUM(G16:G24) -> 1395486.2 | H25: =SUM(C25:G25) -> 6571746.6
B27: NET OPERATING INCOME
B28: NOI | C28: =C13-C25 -> 2100240 | D28: =D13-D25 -> 2161257.9 | E28: =E13-E25 -> 2223990.6 | F28: =F13-F25 -> 2288484 | G28: =G13-G25 -> 2354785.2 | H28: =SUM(C28:G28) -> 11128758 | I28: =IFERROR((G28/C28)^(1/4)-1,0) -> 0.029012364
B29: Less: Replacement Reserves | C29: =Assumptions!$C$30*Assumptions!$C$6*(1+Assumptions!$C$34)^0 -> 60000 | D29: =Assumptions!$C$30*Assumptions!$C$6*(1+Assumptions!$C$34)^1 -> 61500 | E29: =Assumptions!$C$30*Assumptions!$C$6*(1+Assumptions!$C$34)^2 -> 63037.5 | F29: =Assumptions!$C$30*Assumptions!$C$6*(1+Assumptions!$C$34)^3 -> 64613.438 | G29: =Assumptions!$C$30*Assumptions!$C$6*(1+Assumptions!$C$34)^4 -> 66228.773
B30: NOI After Reserves | C30: =C28-C29 -> 2040240 | D30: =D28-D29 -> 2099757.9 | E30: =E28-E29 -> 2160953.1 | F30: =F28-F29 -> 2223870.6 | G30: =G28-G29 -> 2288556.4
B31: NOI Margin (% of EGI) | C31: =C28/C13 -> 0.62956835 | D31: =D28/D13 -> 0.62917617 | E31: =E28/E13 -> 0.62876701 | F31: =F28/F13 -> 0.62834075 | G31: =G28/G13 -> 0.62789727
B34: Private & Confidential · Rescia Properties, LLC · © 2026

Sheet Debt & Equity
B1: Capital Stack & Debt Sizing
B2: Loan metrics, DSCR
B4: CAPITAL STACK
B5: Purchase Price | C5: =Assumptions!$C$5 -> 30000000
B6: Closing Costs | C6: =Assumptions!$C$5*Assumptions!$C$11 -> 450000
B7: Acquisition Fee | C7: =Assumptions!$C$5*Assumptions!$C$12 -> 450000
B8: CapEx Budget | C8: =Assumptions!$C$52*Assumptions!$C$6 -> 2400000
B9: Total Project Cost | C9: =SUM(C5:C8) -> 33300000
B11: DEBT
B12: Loan-to-Cost | C12: =Assumptions!$C$42 -> 0.65
B13: Loan Amount | C13: =C9*C12 -> 21645000
B14: Interest Rate | C14: =Assumptions!$C$43 -> 0.06
B15: Amortization (years) | C15: =Assumptions!$C$44 -> 30
B16: I/O Period (years) | C16: =Assumptions!$C$45 -> 2
B17: Annual I/O Payment | C17: =C13*Assumptions!$C$43 -> 1298700
B18: Annual P&I Payment | C18: =IFERROR(-PMT(Assumptions!$C$43/12,Assumptions!$C$44*12,C13)*12,0) -> 1557272.5
B20: DSCR (Year 3 NOI)
B21: Stabilized NOI (Year 3) | C21: =Proforma!E28 -> 2223990.6
B22: DSCR on I/O | C22: =IFERROR(C21/C17,0) -> 1.7124745
B23: DSCR on P&I | C23: =IFERROR(C21/C18,0) -> 1.4281319
B24: Agency Target DSCR | C24: 1.25
B26: EQUITY
B27: Total Equity Required | C27: =C9-C13 -> 11655000
B28: Equity % | C28: =C27/C9 -> 0.35
B29: Equity Per Unit | C29: =C27/Assumptions!$C$6 -> 58275
B32: Private & Confidential · Rescia Properties, LLC · © 2026

Sheet Returns
B1: Returns Analysis
B2: Equity cash flows, IRR, multiple, CoC
B4: Period | C4: Year 0 | D4: Year 1 | E4: Year 2 | F4: Year 3 | G4: Year 4 | H4: Year 5
B5: PROPERTY CASH FLOWS
B6: NOI (after reserves) | C6: 0 | D6: =Proforma!C30 -> 2040240 | E6: =Proforma!D30 -> 2099757.9 | F6: =Proforma!E30 -> 2160953.1 | G6: =Proforma!F30 -> 2223870.6 | H6: =Proforma!G30 -> 2288556.4
B7: (Less) Debt Service | C7: 0 | D7: =-'Debt & Equity'!C17 -> -1298700 | E7: =-'Debt & Equity'!C17 -> -1298700 | F7: =-'Debt & Equity'!C18 -> -1557272.5 | G7: =-'Debt & Equity'!C18 -> -1557272.5 | H7: =-'Debt & Equity'!C18 -> -1557272.5
B8: Cash Flow from Ops | C8: 0 | D8: =D6+D7 -> 741540 | E8: =E6+E7 -> 801057.9 | F8: =F6+F7 -> 603680.57 | G8: =G6+G7 -> 666598.05 | H8: =H6+H7 -> 731283.9
B10: SALE IN YEAR 5
B11: Gross Sale Price | H11: =Proforma!G28/Assumptions!$C$37 -> 40952786
B12: (Less) Cost of Sale | H12: =-H11*Assumptions!$C$38 -> -819055.72
B13: (Less) Loan Payoff | H13: =-'Debt & Equity'!C13 -> -21645000
B14: Net Sale Proceeds | H14: =SUM(H11:H13) -> 18488730
B16: EQUITY CASH FLOWS
B17: Equity Contribution | C17: =-'Debt & Equity'!C27 -> -11655000 | D17: 0 | E17: 0 | F17: 0 | G17: 0 | H17: 0
B18: Operating Distributions | C18: 0 | D18: =D8 -> 741540 | E18: =E8 -> 801057.9 | F18: =F8 -> 603680.57 | G18: =G8 -> 666598.05 | H18: =H8 -> 731283.9
B19: Sale Distribution | C19: 0 | D19: 0 | E19: 0 | F19: 0 | G19: 0 | H19: =H14 -> 18488730
B20: Total Equity Cash Flow | C20: =C17+C18+C19 -> -11655000 | D20: =D17+D18+D19 -> 741540 | E20: =E17+E18+E19 -> 801057.9 | F20: =F17+F18+F19 -> 603680.57 | G20: =G17+G18+G19 -> 666598.05 | H20: =H17+H18+H19 -> 19220014
B22: METRICS
B23: Project IRR | C23: =IFERROR(IRR(C20:H20),0) -> 0.14845374
B24: Equity Multiple | C24: =IFERROR(SUM(D20:H20)/(-C20),0) -> 1.8904239
B25: Avg Annual CoC | C25: =IFERROR(AVERAGE(D18:H18)/(-C17),0) -> 0.060817854
B26: Year 1 CoC | C26: =IFERROR(D18/(-C17),0) -> 0.063624196
B27: Year 5 CoC (Operating only) | C27: =IFERROR(H18/(-C17),0) -> 0.062744221
B30: Private & Confidential · Rescia Properties, LLC · © 2026

Sheet Sensitivity
B1: Sensitivity Analysis
B2: Approximation: Project IRR by Exit Cap × Rent Growth
C4: Rent Growth (annual)
B5: Exit Cap ↓ | C5: 0.01 | D5: 0.02 | E5: 0.03 | F5: 0.04 | G5: 0.05
B6: 0.05 | C6: =Returns!C23+((Assumptions!$C$37)-B6)*6+(0.01-(Assumptions!$C$33))*3 -> 0.13345374 | D6: =Returns!C23+((Assumptions!$C$37)-B6)*6+(0.02-(Assumptions!$C$33))*3 -> 0.16345374 | E6: =Returns!C23+((Assumptions!$C$37)-B6)*6+(0.03-(Assumptions!$C$33))*3 -> 0.19345374 | F6: =Returns!C23+((Assumptions!$C$37)-B6)*6+(0.04-(Assumptions!$C$33))*3 -> 0.22345374 | G6: =Returns!C23+((Assumptions!$C$37)-B6)*6+(0.05-(Assumptions!$C$33))*3 -> 0.25345374
B7: 0.055 | C7: =Returns!C23+((Assumptions!$C$37)-B7)*6+(0.01-(Assumptions!$C$33))*3 -> 0.10345374 | D7: =Returns!C23+((Assumptions!$C$37)-B7)*6+(0.02-(Assumptions!$C$33))*3 -> 0.13345374 | E7: =Returns!C23+((Assumptions!$C$37)-B7)*6+(0.03-(Assumptions!$C$33))*3 -> 0.16345374 | F7: =Returns!C23+((Assumptions!$C$37)-B7)*6+(0.04-(Assumptions!$C$33))*3 -> 0.19345374 | G7: =Returns!C23+((Assumptions!$C$37)-B7)*6+(0.05-(Assumptions!$C$33))*3 -> 0.22345374
B8: 0.0575 | C8: =Returns!C23+((Assumptions!$C$37)-B8)*6+(0.01-(Assumptions!$C$33))*3 -> 0.088453741 | D8: =Returns!C23+((Assumptions!$C$37)-B8)*6+(0.02-(Assumptions!$C$33))*3 -> 0.11845374 | E8: =Returns!C23+((Assumptions!$C$37)-B8)*6+(0.03-(Assumptions!$C$33))*3 -> 0.14845374 | F8: =Returns!C23+((Assumptions!$C$37)-B8)*6+(0.04-(Assumptions!$C$33))*3 -> 0.17845374 | G8: =Returns!C23+((Assumptions!$C$37)-B8)*6+(0.05-(Assumptions!$C$33))*3 -> 0.20845374
B9: 0.0625 | C9: =Returns!C23+((Assumptions!$C$37)-B9)*6+(0.01-(Assumptions!$C$33))*3 -> 0.058453741 | D9: =Returns!C23+((Assumptions!$C$37)-B9)*6+(0.02-(Assumptions!$C$33))*3 -> 0.088453741 | E9: =Returns!C23+((Assumptions!$C$37)-B9)*6+(0.03-(Assumptions!$C$33))*3 -> 0.11845374 | F9: =Returns!C23+((Assumptions!$C$37)-B9)*6+(0.04-(Assumptions!$C$33))*3 -> 0.14845374 | G9: =Returns!C23+((Assumptions!$C$37)-B9)*6+(0.05-(Assumptions!$C$33))*3 -> 0.17845374
B10: 0.07 | C10: =Returns!C23+((Assumptions!$C$37)-B10)*6+(0.01-(Assumptions!$C$33))*3 -> 0.013453741 | D10: =Returns!C23+((Assumptions!$C$37)-B10)*6+(0.02-(Assumptions!$C$33))*3 -> 0.043453741 | E10: =Returns!C23+((Assumptions!$C$37)-B10)*6+(0.03-(Assumptions!$C$33))*3 -> 0.073453741 | F10: =Returns!C23+((Assumptions!$C$37)-B10)*6+(0.04-(Assumptions!$C$33))*3 -> 0.10345374 | G10: =Returns!C23+((Assumptions!$C$37)-B10)*6+(0.05-(Assumptions!$C$33))*3 -> 0.13345374
B13: NOTE: Linear approximation for screening
B14: • Base case (3% rent, 5.75% exit) highlighted gold.
B15: • Institutional IC threshold: base IRR ≥ 15%, downside ≥ 8%.
B19: Private & Confidential · Rescia Properties, LLC · © 2026

Sheet Sources & Uses
B1: Sources & Uses
B2: Closing capitalization
B4: USES | F4: SOURCES
B5: Purchase Price | C5: =Assumptions!$C$5 -> 30000000 | F5: Senior Loan | G5: ='Debt & Equity'!C13 -> 21645000
B6: Closing Costs | C6: =Assumptions!$C$5*Assumptions!$C$11 -> 450000 | F6: LP Equity (95% of Equity) | G6: =(C10-G5)*0.95 -> 11277878
B7: Acquisition Fee | C7: =Assumptions!$C$5*Assumptions!$C$12 -> 450000 | F7: GP Co-Invest (5%) | G7: =(C10-G5)*0.05 -> 593572.5
B8: CapEx Reserve | C8: =Assumptions!$C$52*Assumptions!$C$6 -> 2400000 | F8: TOTAL SOURCES | G8: =SUM(G5:G7) -> 33516450
B9: Loan Origination Fee | C9: ='Debt & Equity'!C13*Assumptions!$C$47 -> 216450
B10: TOTAL USES | C10: =SUM(C5:C9) -> 33516450
B12: Sources − Uses (should be zero) | C12: =G8-C10 -> 0
B15: Private & Confidential · Rescia Properties, LLC · © 2026
